Workbook
Name ____________HOB1: #REF!
Name ___________HOB1: #REF!
Name __________HOB1: #REF!
Name _________HOB1: #REF!
Name ________HOB1: #REF!
Name _______HOB1: #REF!
Name ______HOB1: #REF!
Name _____HOB1: #REF!
Name ____HOB1: #REF!
Name ___HOB1: #REF!
Name __C100000: #REF!
Name __C608550: #REF!
Name __C90000: #REF!
Name __Cpe111: #REF!
Name __Cpe112: #REF!
Name __Cpe113: #REF!
Name __Cpe114: #REF!
Name __Cpe115: #REF!
Name __Cpe116: #REF!
Name __Cpe118: #REF!
Name __Cpe119: #REF!
Name __Cpe131: #REF!
Name __Cpe135: #REF!
Name __Cpe141: #REF!
Name __Cpe148: #REF!
Name __Cpe151: #REF!
Name __Cpe155: #REF!
Name __Cpe160: #REF!
Name __Cpe171: #REF!
Name __Cpe172: #REF!
Name __Cpe211: #REF!
Name __Cpe212: #REF!
Name __Cpe213: #REF!
Name __Cpe221: #REF!
Name __Cpe222: #REF!
Name __Cpe223: #REF!
Name __Cpe228: #REF!
Name __Cpe231: #REF!
Name __Cpe232: #REF!
Name __Cpe233: #REF!
Name __Cpe234: #REF!
Name __Cpe235: #REF!
Name __Cpe238: #REF!
Name __Cpe239: #REF!
Name __Cpe241: #REF!
Name __Cpe248: #REF!
Name __Cpe251: #REF!
Name __Cpe258: #REF!
Name __Cpe271: #REF!
Name __Cpe272: #REF!
Name __Cpe281: #REF!
Name __Cpe282: #REF!
Name __Cpe283: #REF!
Name __Cpe292: #REF!
Name __Cpe293: #REF!
Name __Cpe294: #REF!
Name __Cpe295: #REF!
Name __Cpe311: #REF!
Name __Cpe312: #REF!
Name __Cpe313: #REF!

Sheet Hyp 2027
A1: HYPOTHESES 2027 - seule zone de saisie du modele | B1: =B9+(B9/$J$9)*$M$5 -> 4.5149631e+09 | C1: =C9+(C9/$J$9)*$M$5 -> 3.4850173e+09 | D1: =D9+(D9/$J$9)*$M$5 -> 53048948 | E1: =E9+(E9/$J$9)*$M$5 -> 5.9627164e+09 | F1: =F9+(F9/$J$9)*$M$5 -> 6.0608194e+08 | G1: =G9+(G9/$J$9)*$M$5 -> 8.987445e+08 | H1: =H9+(H9/$J$9)*$M$5 -> 8.685728e+08 | I1: =I9+(I9/$J$9)*$M$5 -> 1.6740804e+09
A2: Bleu = saisie (fichiers M01-M06 et SAZ Marge Tech FORECAST.xlsx) | Noir = formule | B2: =(B12/$J$12)*$L$11+B12 -> 5.4545011e+09 | C2: =(C11/$J$11)*$L$11+C11 -> 3.4783853e+09 | D2: =(D11/$J$11)*$L$11+D11 -> 64062804 | E2: =(E11/$J$11)*$L$11+E11 -> 6.3107771e+09 | F2: =(F11/$J$11)*$L$11+F11 -> 5.9281545e+08 | G2: =(G11/$J$11)*$L$11+G11 -> 9.0604974e+08 | H2: =(H11/$J$11)*$L$11+H11 -> 8.6150106e+08 | I2: =(I11/$J$11)*$L$11+I11 -> 1.7141771e+09 | J2: =SUM(B2:I2) -> 1.938227e+10
A3: DIRECT 2026 YTD (fichiers M01-M06) | B3: Motor | C3: Health | D3: Worker injury | E3: Fire | F3: Engineering | G3: Liability | H3: Miscellaneous | I3: Transport | J3: Total | O3: Motor | P3: Health | Q3: Worker injury | R3: Fire | S3: Engineering | T3: Liability | U3: Miscellaneous | V3: Transport
A5: Primes emises M01 | B5: 1.9545379e+09 | C5: 1.88643e+09 | D5: 8614310.8 | E5: 7.4610775e+08 | F5: 1.0837485e+08 | G5: 39441442 | H5: 3.5224116e+08 | I5: 16638269 | J5: =SUM(B5:I5) -> 5.1123857e+09 | K5: =5542385658 -> 5542385658 | L5: =K5-J5 -> 4.3e+08 | M5: 1500000000
A6: Primes emises M02 | B6: 2.4105843e+09 | C6: 2.2056225e+09 | D6: 25094566 | E6: 2.3201667e+09 | F6: 2.7718729e+08 | G6: 2.0909543e+08 | H6: 4.8835035e+08 | I6: 1.0230056e+09 | J6: =SUM(B6:I6) -> 8959106785 | K6: 8759106785 | L6: =K6-J6 -> -200000000 | O6: =B6>B5 -> TRUE | P6: =C6>C5 -> TRUE | Q6: =D6>D5 -> TRUE | R6: =E6>E5 -> TRUE | S6: =F6>F5 -> TRUE | T6: =G6>G5 -> TRUE | U6: =H6>H5 -> TRUE | V6: =I6>I5 -> TRUE
A7: Primes emises M03 | B7: 2.8687888e+09 | C7: 2.5569658e+09 | D7: 25814243 | E7: =2392440950.21417+1500000000 -> 3.892441e+09 | F7: 3.6386719e+08 | G7: 2.3796607e+08 | H7: =697612996.267642-100000000 -> 5.97613e+08 | I7: 1.1210727e+09 | J7: =SUM(B7:I7) -> 1.1664529e+10 | K7: 10264528782 | L7: =K7-J7 -> -1.4e+09 | O7: =B7>B6 -> TRUE | P7: =C7>C6 -> TRUE | Q7: =D7>D6 -> TRUE | R7: =E7>E6 -> TRUE | S7: =F7>F6 -> TRUE | T7: =G7>G6 -> TRUE | U7: =H7>H6 -> TRUE | V7: =I7>I6 -> TRUE
A8: Primes emises M04 | B8: 3.0831911e+09 | C8: =2567548952.1017+200000000 -> 2.767549e+09 | D8: =25748616.4745879+10000000 -> 35748616 | E8: 5.1439292e+09 | F8: 4.4951478e+08 | G8: 6.9718804e+08 | H8: 6.874981e+08 | I8: 1.1348398e+09 | J8: =SUM(B8:I8) -> 1.3999459e+10 | K8: 15289458632 | L8: =K8-J8 -> 1.29e+09 | O8: =B8>B7 -> TRUE | P8: =C8>C7 -> TRUE | Q8: =D8>D7 -> TRUE | R8: =E8>E7 -> TRUE | S8: =F8>F7 -> TRUE | T8: =G8>G7 -> TRUE | U8: =H8>H7 -> TRUE | V8: =I8>I7 -> TRUE
A9: Primes emises M05 | B9: 4.1400331e+09 | C9: 3.1956157e+09 | D9: 48643676 | E9: =6167562601.13338-700000000 -> 5.4675626e+09 | F9: 5.5575189e+08 | G9: =874111273.352422-50000000 -> 8.2411127e+08 | H9: =896445087.426672-100000000 -> 7.9644509e+08 | I9: 1.535062e+09 | J9: =SUM(B9:I9) -> 1.6563225e+10 | K9: 16113854026 | L9: =K9-J9 -> -4.4937128e+08 | O9: =B9>B8 -> TRUE | P9: =C9>C8 -> TRUE | Q9: =D9>D8 -> TRUE | R9: =E9>E8 -> TRUE | S9: =F9>F8 -> TRUE | T9: =G9>G8 -> TRUE | U9: =H9>H8 -> TRUE | V9: =I9>I8 -> TRUE
A10: Primes emises M06 | B10: =4068649041.64682+200000000+200000000 -> 4.468649e+09 | C10: =2927804903.89432+400000000 -> 3.3278049e+09 | D10: 60891855 | E10: 6.2965674e+09 | F10: 5.6600044e+08 | G10: 8.7411127e+08 | H10: =896445087.426672-60000000 -> 8.3644509e+08 | I10: 1.633055e+09 | J10: =SUM(B10:I10) -> 1.8063525e+10 | K10: 17187985458 | L10: =K10-J10 -> -8.7553955e+08 | O10: =B10>B9 -> TRUE | P10: =C10>C9 -> TRUE | Q10: =D10>D9 -> TRUE | R10: =E10>E9 -> TRUE | S10: =F10>F9 -> TRUE | T10: =G10>G9 -> TRUE | U10: =H10>H9 -> TRUE | V10: =I10>I9 -> TRUE
A11: Primes emises M07 | B11: =4569040691.11808+200000000 -> 4.7690407e+09 | C11: =3223456698.09457+300000000 -> 3.5234567e+09 | D11: 64892902 | E11: 6.3925494e+09 | F11: 6.0049689e+08 | G11: 9.1778994e+08 | H11: 8.7266401e+08 | I11: 1736388630 | J11: =SUM(B11:I11) -> 1.8877279e+10 | K11: 18635804603 | L11: =K11-J11 -> -2.4147459e+08 | O11: =B11>B10 -> TRUE | P11: =C11>C10 -> TRUE | Q11: =D11>D10 -> TRUE | R11: =E11>E10 -> TRUE | S11: =F11>F10 -> TRUE | T11: =G11>G10 -> TRUE | U11: =H11>H10 -> TRUE | V11: =I11>I10 -> TRUE
A12: Primes emises M08 (2025) | B12: 5516071353 | C12: 3704847289 | D12: 65279929 | E12: 6498115245 | F12: 688956997 | G12: 2433459825 | H12: 904690916 | I12: 1.8222483e+09 | J12: =SUM(B12:I12) -> 2.163367e+10 | L12: =K12-J12 -> -2.163367e+10 | O12: =B12>B11 -> TRUE | P12: =C12>C11 -> TRUE | Q12: =D12>D11 -> TRUE | R12: =E12>E11 -> TRUE | S12: =F12>F11 -> TRUE | T12: =G12>G11 -> TRUE | U12: =H12>H11 -> TRUE | V12: =I12>I11 -> TRUE
A13: Primes emises M09 | B13: 5851081097 | C13: 3876660359 | D13: 66922967 | E13: 6891818224 | F13: 692645455 | G13: 2898741452 | H13: 9.3132971e+08 | I13: 1957192660 | J13: =SUM(B13:I13) -> 2.3166392e+10 | L13: =K13-J13 -> -2.3166392e+10 | O13: =B13>B12 -> TRUE | P13: =C13>C12 -> TRUE | Q13: =D13>D12 -> TRUE | R13: =E13>E12 -> TRUE | S13: =F13>F12 -> TRUE | T13: =G13>G12 -> TRUE | U13: =H13>H12 -> TRUE | V13: =I13>I12 -> TRUE
A14: Primes emises M10 | B14: 6.2599616e+09 | C14: 4148277719 | D14: 70127240 | E14: 7.1844536e+09 | F14: 7.0207769e+08 | G14: 2949978253 | H14: 1000090510 | I14: 2095028158 | J14: =SUM(B14:I14) -> 2.4409995e+10 | L14: =K14-J14 -> -2.4409995e+10 | O14: =B14>B13 -> TRUE | P14: =C14>C13 -> TRUE | Q14: =D14>D13 -> TRUE | R14: =E14>E13 -> TRUE | S14: =F14>F13 -> TRUE | T14: =G14>G13 -> TRUE | U14: =H14>H13 -> TRUE | V14: =I14>I13 -> TRUE
A15: Primes emises M11 | B15: 6657885305 | C15: 4342479221 | D15: 72768637 | E15: 7302571869 | F15: 740428992 | G15: 3060788157 | H15: 1173135828 | I15: 2286613640 | J15: =SUM(B15:I15) -> 25636671649 | L15: =K15-J15 -> -25636671649 | O15: =B15>B14 -> TRUE | P15: =C15>C14 -> TRUE | Q15: =D15>D14 -> TRUE | R15: =E15>E14 -> TRUE | S15: =F15>F14 -> TRUE | T15: =G15>G14 -> TRUE | U15: =H15>H14 -> TRUE | V15: =I15>I14 -> TRUE
A16: Primes emises M12 | B16: 6963552336 | C16: 4396984788 | D16: 77934224 | E16: 7485337118 | F16: 793216278 | G16: 3121991319 | H16: 1211281670 | I16: 2364392134 | J16: =SUM(B16:I16) -> 26414689867 | L16: =K16-J16 -> -26414689867 | O16: =B16>B15 -> TRUE | P16: =C16>C15 -> TRUE | Q16: =D16>D15 -> TRUE | R16: =E16>E15 -> TRUE | S16: =F16>F15 -> TRUE | T16: =G16>G15 -> TRUE | U16: =H16>H15 -> TRUE | V16: =I16>I15 -> TRUE
L17: =K17-J17 -> 0
A19: Sinistres payes Per. M01 | B19: 949634 | C19: 463425 | D19: 0 | E19: 0 | F19: 0 | G19: 0 | H19: 0 | I19: -3089000
A20: Sinistres payes Per. M02 | B20: 2192777 | C20: 14632418 | D20: 0 | E20: 0 | F20: 0 | G20: 0 | H20: 0 | I20: 330000
A21: Sinistres payes Per. M03 | B21: 10974365 | C21: 141758782 | D21: 0 | E21: 0 | F21: 0 | G21: 0 | H21: 0 | I21: 3762494
A22: Sinistres payes Per. M04 | B22: 55301048 | C22: 317091145 | D22: 0 | E22: 0 | F22: 0 | G22: 444050 | H22: 0 | I22: 12463598 | K22: 9.3132971e+08
A23: Sinistres payes Per. M05 | B23: 95344622 | C23: 604911137 | D23: 0 | E23: 0 | F23: 0 | G23: 829050 | H23: 0 | I23: 14164104 | K23: 1000090510
A24: Sinistres payes Per. M06 | B24: 146149062 | C24: 839203521 | D24: 0 | E24: 550999 | F24: 0 | G24: 954050 | H24: 0 | I24: 94382038 | K24: 1173135828
A25: Sinistres payes Per. M07 | B25: 211016709 | C25: 1072120441 | D25: 0 | E25: 600999 | F25: 0 | G25: 1369882 | H25: 0 | I25: 94926410
A26: Sinistres payes Per. M08 (2025) | B26: 3.1000322e+08 | C26: 1292606030 | D26: 0 | E26: 32359188 | F26: 656218 | G26: 0 | H26: 0 | I26: 107013568
A27: Sinistres payes Per. M09 | B27: 3.9851989e+08 | C27: 1535820319 | D27: 0 | E27: 33170472 | F27: 656218 | G27: 0 | H27: 0 | I27: 116236704
A28: Sinistres payes Per. M10 | B28: 5.5058135e+08 | C28: 1805140581 | D28: 0 | E28: 43782290 | F28: 656218 | G28: 0 | H28: 0 | I28: 130998797
A29: Sinistres payes Per. M11 | B29: 6.784687e+08 | C29: 2080986023 | D29: 0 | E29: 50117618 | F29: 4218680 | G29: 1389287 | H29: 0 | I29: 173479878
A30: Sinistres payes Per. M12 | B30: 7.5118785e+08 | C30: 2082958327 | D30: 0 | E30: 661074779 | F30: 7511861 | G30: 1389287 | H30: 0 | I30: 707705435
A32: Sinistres payes Ant. M01 | B32: 239790513 | C32: 543859743 | D32: 0 | E32: 32114472 | F32: 1517222 | G32: 57060000 | H32: 0 | I32: 7300000
A33: Sinistres payes Ant. M02 | B33: 548926130 | C33: 777327039 | D33: 0 | E33: 93435634 | F33: 1517222 | G33: 80540705 | H33: 0 | I33: 25559022
A34: Sinistres payes Ant. M03 | B34: 711990944 | C34: 922709764 | D34: 0 | E34: 133368400 | F34: 1517222 | G34: 82655330 | H34: 0 | I34: 17115528
A35: Sinistres payes Ant. M04 | B35: 1032616588 | C35: 1022151662 | D35: 0 | E35: 417365766 | F35: 2396324 | G35: 73550013 | H35: 248734 | I35: 58410334
A36: Sinistres payes Ant. M05 | B36: 1143280554 | C36: 1034722223 | D36: 0 | E36: 499444317 | F36: 4850950 | G36: 81527291 | H36: 2605526 | I36: 132805300
A37: Sinistres payes Ant. M06 | B37: 1338652150 | C37: 1037476740 | D37: 0 | E37: 505479166 | F37: 12354273 | G37: 81961786 | H37: 2615526 | I37: 202559309
... A76: Variation REC M12 | B76: -27758870 | C76: -61681095 | D76: 2206525 | E76: -3.1399389e+08 | F76: -2.0583621e+08 | G76: -1.3588032e+08 | H76: -2.1866166e+08 | I76: -71053474
A78: REASS 2026 YTD (fichiers M01-M06) | B78: Motor | C78: Health | D78: Worker injury | E78: Fire | F78: Engineering | G78: Liability | H78: Miscellaneous | I78: Transport
A79: Primes cedees M01 | B79: 83266640 | C79: 19654609 | D79: 226891.52 | E79: 4.8145194e+08 | F79: 2.209327e+08 | G79: 29555088 | H79: 1.2694383e+08 | I79: 5921901.6
A80: Primes cedees M02 | B80: 65366210 | C80: 49823447 | D80: 638518.95 | E80: 1.2526641e+09 | F80: 82436581 | G80: 65504427 | H80: 3.0696606e+08 | I80: 2.3814546e+08
A81: Primes cedees M03 | B81: 93115430 | C81: 65604928 | D81: 687950.82 | E81: 1.3664674e+09 | F81: 2.8694842e+08 | G81: 68328031 | H81: 4.0521064e+08 | I81: 2.8232789e+08
A82: Primes cedees M04 | B82: 1.1506391e+08 | C82: 81138031 | D82: 724945.38 | E82: 4.3421475e+09 | F82: 3.2476051e+08 | G82: 4.3999423e+08 | H82: 4.4129593e+08 | I82: 2.9927304e+08
...

Sheet Direct Local
A1: =87% -> 0.87 | B1: 0.18231671 | C1: 0.14579012 | D1: 0.23202849 | E1: 0.13510841 | F1: 0.13344372 | G1: 0.12726029 | H1: 0.14632056 | I1: 0.18718791
B2: 0.0994 | C2: 0.0682 | D2: 0.17468 | E2: 0.111 | F2: 0.17468 | G2: 0.27468 | H2: 0.17468 | I2: 0.08468 | EJ2: =43550000/12 -> 3629166.7 | EK2: =25375000/7 -> 3625000
B3: 2619580477 | C3: 1563144534 | D3: 7138040 | E3: 618244114 | F3: 446111277 | G3: 32682196 | H3: 291876106 | I3: 13786899
A4: Local GAAP | B4: SanlamAllianz LIC Tool | E4: 46388 | M4: SanlamAllianz LIC Tool | P4: 46419 | Y4: SanlamAllianz LIC Tool | AC4: 46447 | AK4: SanlamAllianz LIC Tool | AO4: 46478 | AW4: SanlamAllianz LIC Tool | BA4: 46508 | BI4: SanlamAllianz LIC Tool | BM4: 46539 | BU4: SanlamAllianz LIC Tool | BY4: 46569 | CG4: SanlamAllianz LIC Tool | CK4: Aout 27 | CS4: SanlamAllianz LIC Tool | CW4: 46631 | DE4: SanlamAllianz LIC Tool | DI4: 46661 | DQ4: SanlamAllianz LIC Tool | DU4: 46692 | EC4: SanlamAllianz LIC Tool | EG4: 46722
A5: F CFA | B5: Motor | C5: Health | D5: Worker injury | E5: Fire | F5: Engineering | G5: Liability | H5: Miscellaneous | I5: Transport | M5: Motor | N5: Health | O5: Worker injury | P5: Fire | Q5: Engineering | R5: Liability | S5: Miscellaneous | T5: Transport | Y5: Motor | Z5: Health | AA5: Worker injury | AB5: Fire | AC5: Engineering | AD5: Liability | AE5: Miscellaneous | AF5: Transport | AK5: Motor | AL5: Health | AM5: Worker injury | AN5: Fire | AO5: Engineering | AP5: Liability | AQ5: Miscellaneous | AR5: Transport | AW5: Motor | AX5: Health | AY5: Worker injury | AZ5: Fire | BA5: Engineering | BB5: Liability | BC5: Miscellaneous | BD5: Transport | BI5: Motor | BJ5: Health | BK5: Worker injury | BL5: Fire | BM5: Engineering | BN5: Liability | BO5: Miscellaneous | BP5: Transport | BU5: Motor | BV5: Health | BW5: Worker injury | BX5: Fire | BY5: Engineering | BZ5: Liability | CA5: Miscellaneous | CB5: Transport | CG5: Motor | CH5: Health | CI5: Worker injury | CJ5: Fire | CK5: Engineering | CL5: Liability | CM5: Miscellaneous | CN5: Transport | CS5: Motor | CT5: Health | CU5: Worker injury | CV5: Fire | CW5: Engineering | CX5: Liability | CY5: Miscellaneous | CZ5: Transport | DE5: Motor | DF5: Health | DG5: Worker injury | DH5: Fire | DI5: Engineering | DJ5: Liability | DK5: Miscellaneous | DL5: Transport | DQ5: Motor | DR5: Health | DS5: Worker injury | DT5: Fire | DU5: Engineering | DV5: Liability | DW5: Miscellaneous | DX5: Transport | EC5: Motor | ED5: Health | EE5: Worker injury | EF5: Fire | EG5: Engineering | EH5: Liability | EI5: Miscellaneous | EJ5: Transport
B6: Automobile | C6: Santé | D6: Accident corporel | E6: Incendie | F6: BDM - Construction | G6: RC - RC Déc | H6: RD | I6: Transport | J6: Corporate | K6: Global | M6: Automobile | N6: Santé | O6: Accident corporel | P6: Incendie | Q6: BDM - Construction | R6: RC - RC Déc | S6: RD | T6: Transport | U6: Corporate | V6: Global | Y6: Automobile | Z6: Santé | AA6: Accident corporel | AB6: Incendie | AC6: BDM - Construction | AD6: RC - RC Déc | AE6: RD | AF6: Transport | AG6: Corporate | AH6: Global | AK6: Automobile | AL6: Santé | AM6: Accident corporel | AN6: Incendie | AO6: BDM - Construction | AP6: RC - RC Déc | AQ6: RD | AR6: Transport | AS6: Corporate | AT6: Global | AW6: Automobile | AX6: Santé | AY6: Accident corporel | AZ6: Incendie | BA6: BDM - Construction | BB6: RC - RC Déc | BC6: RD | BD6: Transport | BE6: Corporate | BF6: Global | BI6: Automobile | BJ6: Santé | BK6: Accident corporel | BL6: Incendie | BM6: BDM - Construction | BN6: RC - RC Déc | BO6: RD | BP6: Transport | BQ6: Corporate | BR6: Global | BU6: Automobile | BV6: Santé | BW6: Accident corporel | BX6: Incendie | BY6: BDM - Construction | BZ6: RC - RC Déc | CA6: RD | CB6: Transport | CC6: Corporate | CD6: Global | CG6: Automobile | CH6: Santé | CI6: Accident corporel | CJ6: Incendie | CK6: BDM - Construction | CL6: RC - RC Déc | CM6: RD | CN6: Transport | CO6: Corporate | CP6: Global | CS6: Automobile | CT6: Santé | CU6: Accident corporel | CV6: Incendie | CW6: BDM - Construction | CX6: RC - RC Déc | CY6: RD | CZ6: Transport | DA6: Corporate | DB6: Global | DE6: Automobile | DF6: Santé | DG6: Accident corporel | DH6: Incendie | DI6: BDM - Construction | DJ6: RC - RC Déc | DK6: RD | DL6: Transport | DM6: Corporate | DN6: Global | DQ6: Automobile | DR6: Santé | DS6: Accident corporel | DT6: Incendie | DU6: BDM - Construction | DV6: RC - RC Déc | DW6: RD | DX6: Transport | DY6: Corporate | DZ6: Global | EC6: Automobile | ED6: Santé | EE6: Accident corporel | EF6: Incendie | EG6: BDM - Construction | EH6: RC - RC Déc | EI6: RD | EJ6: Transport | EK6: Corporate | EL6: Global
A7: Primes Emises | B7: ='Hyp 2027'!B5*'Hyp 2027'!B166 -> 2.0666856e+09 | C7: ='Hyp 2027'!C5*'Hyp 2027'!C166 -> 1.8778018e+09 | D7: ='Hyp 2027'!D5*'Hyp 2027'!D166 -> 10053583 | E7: ='Hyp 2027'!E5*'Hyp 2027'!E166 -> 8.9002401e+08 | F7: ='Hyp 2027'!F5*'Hyp 2027'!F166 -> 1.2721586e+08 | G7: ='Hyp 2027'!G5*'Hyp 2027'!G166 -> 27995224 | H7: ='Hyp 2027'!H5*'Hyp 2027'!H166 -> 7.0638702e+08 | I7: ='Hyp 2027'!I5*'Hyp 2027'!I166 -> 20050105 | J7: =SUM(D7:I7) -> 1.7817258e+09 | K7: =B7+C7+J7 -> 5.7262132e+09 | L7: ok | M7: ='Hyp 2027'!B6*'Hyp 2027'!B166 -> 2.5488992e+09 | N7: ='Hyp 2027'!C6*'Hyp 2027'!C166 -> 2.1955344e+09 | O7: ='Hyp 2027'!D6*'Hyp 2027'!D166 -> 29287346 | P7: ='Hyp 2027'!E6*'Hyp 2027'!E166 -> 2.7677022e+09 | Q7: ='Hyp 2027'!F6*'Hyp 2027'!F166 -> 3.2537641e+08 | R7: ='Hyp 2027'!G6*'Hyp 2027'!G166 -> 1.4841429e+08 | S7: ='Hyp 2027'!H6*'Hyp 2027'!H166 -> 9.7934139e+08 | T7: ='Hyp 2027'!I6*'Hyp 2027'!I166 -> 1.2327826e+09 | U7: =SUM(O7:T7) -> 5.4829043e+09 | V7: =M7+N7+U7 -> 1.0227338e+10 | Y7: ='Hyp 2027'!B7*'Hyp 2027'!B$166 -> 3.0333946e+09 | Z7: ='Hyp 2027'!C7*'Hyp 2027'!C$166 -> 2.5452707e+09 | AA7: ='Hyp 2027'!D7*'Hyp 2027'!D$166 -> 30127265 | AB7: ='Hyp 2027'!E7*'Hyp 2027'!E$166 -> 4.6432515e+09 | AC7: ='Hyp 2027'!F7*'Hyp 2027'!F$166 -> 4.2712564e+08 | AD7: ='Hyp 2027'!G7*'Hyp 2027'!G$166 -> 1.6890644e+08 | AE7: ='Hyp 2027'!H7*'Hyp 2027'!H$166 -> 1.1984575e+09 | AF7: ='Hyp 2027'!I7*'Hyp 2027'!I$166 -> 1.3509593e+09 | AG7: =SUM(AA7:AF7) -> 7.8188276e+09 | AH7: =Y7+Z7+AG7 -> 1.3397493e+10 | AK7: ='Hyp 2027'!B8*'Hyp 2027'!B$166 -> 3.2600989e+09 | AL7: ='Hyp 2027'!C8*'Hyp 2027'!C$166 -> 2.7548907e+09 | AM7: ='Hyp 2027'!D8*'Hyp 2027'!D$166 -> 41721466 | AN7: ='Hyp 2027'!E8*'Hyp 2027'!E$166 -> 6.1361385e+09 | AO7: ='Hyp 2027'!F8*'Hyp 2027'!F$166 -> 5.276631e+08 | AP7: ='Hyp 2027'!G8*'Hyp 2027'!G$166 -> 4.9485857e+08 | AQ7: ='Hyp 2027'!H8*'Hyp 2027'!H$166 -> 1.3787138e+09 | AR7: ='Hyp 2027'!I8*'Hyp 2027'!I$166 -> 1.3675495e+09 | AS7: =SUM(AM7:AR7) -> 9.9466449e+09 | AT7: =AK7+AL7+AS7 -> 1.5961634e+10 | AW7: ='Hyp 2027'!B9*'Hyp 2027'!B$166 -> 4.3775806e+09 | AX7: ='Hyp 2027'!C9*'Hyp 2027'!C$166 -> 3.1809995e+09 | AY7: ='Hyp 2027'!D9*'Hyp 2027'!D$166 -> 56771021 | AZ7: ='Hyp 2027'!E9*'Hyp 2027'!E$166 -> 6.5221974e+09 | BA7: ='Hyp 2027'!F9*'Hyp 2027'!F$166 -> 6.5236958e+08 | BB7: ='Hyp 2027'!G9*'Hyp 2027'!G$166 -> 5.8494767e+08 | BC7: ='Hyp 2027'!H9*'Hyp 2027'!H$166 -> 1.5971969e+09 | BD7: ='Hyp 2027'!I9*'Hyp 2027'!I$166 -> 1.849841e+09 | BE7: =SUM(AY7:BD7) -> 1.1263323e+10 | BF7: =AW7+AX7+BE7 -> 1.8821904e+10 | BI7: ='Hyp 2027'!B10*'Hyp 2027'!B$166 -> 4.7250519e+09 | BJ7: ='Hyp 2027'!C10*'Hyp 2027'!C$166 -> 3.3125841e+09 | BK7: ='Hyp 2027'!D10*'Hyp 2027'!D$166 -> 71065615 | BL7: ='Hyp 2027'!E10*'Hyp 2027'!E$166 -> 7.5111084e+09 | BM7: ='Hyp 2027'!F10*'Hyp 2027'!F$166 -> 6.6439984e+08 | BN7: ='Hyp 2027'!G10*'Hyp 2027'!G$166 -> 6.2043728e+08 | BO7: ='Hyp 2027'!H10*'Hyp 2027'!H$166 -> 1.6774132e+09 | BP7: ='Hyp 2027'!I10*'Hyp 2027'!I166 -> 1.9679284e+09 | BQ7: =SUM(BK7:BP7) -> 1.2512353e+10 | BR7: =BI7+BJ7+BQ7 -> 2.0549989e+10 | BU7: ='Hyp 2027'!B11*'Hyp 2027'!B166 -> 5.0426794e+09 | BV7: ='Hyp 2027'!C11*'Hyp 2027'!C166 -> 3.507341e+09 | BW7: ='Hyp 2027'!D11*'Hyp 2027'!D166 -> 75735154 | BX7: ='Hyp 2027'!E11*'Hyp 2027'!E166 -> 7.6256043e+09 | BY7: ='Hyp 2027'!F11*'Hyp 2027'!F166 -> 7.0489351e+08 | BZ7: ='Hyp 2027'!G11*'Hyp 2027'!G166 -> 6.5144005e+08 | CA7: ='Hyp 2027'!H11*'Hyp 2027'!H166 -> 1.7500469e+09 | CB7: ='Hyp 2027'!I11*'Hyp 2027'!I166 -> 2.0924516e+09 | CC7: =SUM(BW7:CB7) -> 1.2900171e+10 | CD7: =BU7+BV7+CC7 -> 2.1450192e+10 | CG7: ='Hyp 2027'!B12*'Hyp 2027'!B166 -> 5.8325733e+09 | CH7: ='Hyp 2027'!C12*'Hyp 2027'!C166 -> 3.687902e+09 | CI7: ='Hyp 2027'!D12*'Hyp 2027'!D166 -> 76186845 | CJ7: ='Hyp 2027'!E12*'Hyp 2027'!E166 -> 7.7515327e+09 | CK7: ='Hyp 2027'!F12*'Hyp 2027'!F166 -> 8.0873244e+08 | CL7: ='Hyp 2027'!G12*'Hyp 2027'!G166 -> 1.7272506e+09 | CM7: ='Hyp 2027'!H12*'Hyp 2027'!H166 -> 1.8142738e+09 | CN7: ='Hyp 2027'!I12*'Hyp 2027'!I166 -> 2.1959177e+09 | CO7: =SUM(CI7:CN7) -> 1.4373894e+10 | CP7: =CG7+CH7+CO7 -> 2.3894369e+10 | CS7: ='Hyp 2027'!B13*'Hyp 2027'!B166 -> 6.1868053e+09 | CT7: ='Hyp 2027'!C13*'Hyp 2027'!C166 -> 3.8589292e+09 | CU7: ='Hyp 2027'!D13*'Hyp 2027'!D166 -> 78104401 | CV7: ='Hyp 2027'!E13*'Hyp 2027'!E166 -> 8.2211768e+09 | CW7: ='Hyp 2027'!F13*'Hyp 2027'!F166 -> 8.1306214e+08 | CX7: ='Hyp 2027'!G13*'Hyp 2027'!G166 -> 2.0575038e+09 | CY7: ='Hyp 2027'!H13*'Hyp 2027'!H166 -> 1.8676955e+09 | CZ7: ='Hyp 2027'!I13*'Hyp 2027'!I166 -> 2.3585336e+09 | DA7: =SUM(CU7:CZ7) -> 1.5396076e+10 | DB7: =CS7+CT7+DA7 -> 2.5441811e+10 | DE7: ='Hyp 2027'!B14*'Hyp 2027'!B166 -> 6.6191466e+09 | DF7: ='Hyp 2027'!C14*'Hyp 2027'!C166 -> 4.1293042e+09 | DG7: ='Hyp 2027'!D14*'Hyp 2027'!D166 -> 81844041 | DH7: ='Hyp 2027'!E14*'Hyp 2027'!E166 -> 8.5702584e+09 | DI7: ='Hyp 2027'!F14*'Hyp 2027'!F166 -> 8.2413417e+08 | DJ7: ='Hyp 2027'!G14*'Hyp 2027'!G166 -> 2.0938713e+09 | DK7: ='Hyp 2027'!H14*'Hyp 2027'!H166 -> 2.0055889e+09 | DL7: ='Hyp 2027'!I14*'Hyp 2027'!I166 -> 2.5246336e+09 | DM7: =SUM(DG7:DL7) -> 1.610033e+10 | DN7: =DE7+DF7+DM7 -> 2.6848781e+10 | DQ7: ='Hyp 2027'!B15*'Hyp 2027'!B166 -> 7.0399024e+09 | DR7: ='Hyp 2027'!C15*'Hyp 2027'!C166 -> 4.3226175e+09 | DS7: ='Hyp 2027'!D15*'Hyp 2027'!D166 -> 84926760 | DT7: ='Hyp 2027'!E15*'Hyp 2027'!E166 -> 8.7111604e+09 | DU7: ='Hyp 2027'!F15*'Hyp 2027'!F166 -> 8.6915286e+08 | DV7: ='Hyp 2027'!G15*'Hyp 2027'!G166 -> 2.1725233e+09 | DW7: ='Hyp 2027'!H15*'Hyp 2027'!H166 -> 2.3526152e+09 | DX7: ='Hyp 2027'!I15*'Hyp 2027'!I166 -> 2.7555055e+09 | DY7: =SUM(DS7:DX7) -> 1.6945884e+10 | DZ7: =DQ7+DR7+DY7 -> 2.8308404e+10 | EC7: ='Hyp 2027'!B16*'Hyp 2027'!B166 -> 7.3631081e+09 | ED7: ='Hyp 2027'!C16*'Hyp 2027'!C166 -> 4.3768737e+09 | EE7: ='Hyp 2027'!D16*'Hyp 2027'!D166 -> 90955409 | EF7: ='Hyp 2027'!E16*'Hyp 2027'!E166 -> 8.9291791e+09 | EG7: ='Hyp 2027'!F16*'Hyp 2027'!F166 -> 9.3111724e+08 | EH7: ='Hyp 2027'!G16*'Hyp 2027'!G166 -> 2.2159648e+09 | EI7: ='Hyp 2027'!H16*'Hyp 2027'!H166 -> 2.4291132e+09 | EJ7: ='Hyp 2027'!I16*'Hyp 2027'!I166 -> 2.8492332e+09 | EK7: =SUM(EE7:EJ7) -> 1.7445563e+10 | EL7: =EC7+ED7+EK7 -> 2.9185545e+10
A8: PAP Ouverture | B8: 0 | C8: 0 | D8: 0 | E8: 0 | F8: 0 | G8: 0 | H8: 0 | I8: 0 | J8: =SUM(D8:I8) -> 0 | K8: =B8+C8+J8 -> 0 | M8: =B8*M135 -> 0 | N8: =C8*N135 -> 0 | O8: =D8*O135 -> 0 | P8: =E8*P135 -> 0 | Q8: =F8*Q135 -> 0 | R8: =G8*R135 -> 0 | S8: =H8*S135 -> 0 | T8: =I8*T135 -> 0 | U8: =SUM(O8:T8) -> 0 | V8: =M8+N8+U8 -> 0 | Y8: =M8*Y135 -> 0 | Z8: =N8*Z135 -> 0 | AA8: =O8*AA135 -> 0 | AB8: =P8*AB135 -> 0 | AC8: =Q8*AC135 -> 0 | AD8: =R8*AD135 -> 0 | AE8: =S8*AE135 -> 0 | AF8: =T8*AF135 -> 0 | AG8: =SUM(AA8:AF8) -> 0 | AH8: =Y8+Z8+AG8 -> 0 | AK8: =Y8*AK135 -> 0 | AL8: =Z8*AL135 -> 0 | AM8: =AA8*AM135 -> 0 | AN8: =AB8*AN135 -> 0 | AO8: =AC8*AO135 -> 0 | AP8: =AD8*AP135 -> 0 | AQ8: =AE8*AQ135 -> 0 | AR8: =AF8*AR135 -> 0 | AS8: =AG8*AS135 -> 0 | AT8: =AK8+AL8+AS8 -> 0 | AW8: =AK8*AW135 -> 0 | AX8: =AL8*AX135 -> 0 | AY8: =AM8*AY135 -> 0 | AZ8: =AN8*AZ135 -> 0 | BA8: =AO8*BA135 -> 0 | BB8: =AP8*BB135 -> 0 | BC8: =AQ8*BC135 -> 0 | BD8: =AR8*BD135 -> 0 | BE8: =AS8*BE135 -> 0 | BF8: =AW8+AX8+BE8 -> 0 | BI8: =AW8*BI135 -> 0 | BJ8: =AX8*BJ135 -> 0 | BK8: =AY8*BK135 -> 0 | BL8: =AZ8*BL135 -> 0 | BM8: =BA8*BM135 -> 0 | BN8: =BB8*BN135 -> 0 | BO8: =BC8*BO135 -> 0 | BP8: =BD8*BP135 -> 0 | BQ8: =BE8*BQ135 -> 0 | BR8: =BI8+BJ8+BQ8 -> 0 | BU8: =BI8*BU135 -> 0 | BV8: =BJ8*BV135 -> 0 | BW8: =BK8*BW135 -> 0 | BX8: =BL8*BX135 -> 0 | BY8: =BM8*BY135 -> 0 | BZ8: =BN8*BZ135 -> 0 | CA8: =BO8*CA135 -> 0 | CB8: =BP8*CB135 -> 0 | CC8: =BQ8*CC135 -> 0 | CD8: =BU8+BV8+CC8 -> 0 | CG8: =BU8*CG135 -> 0 | CH8: =BV8*CH135 -> 0 | CI8: =BW8*CI135 -> 0 | CJ8: =BX8*CJ135 -> 0 | CK8: =BY8*CK135 -> 0 | CL8: =BZ8*CL135 -> 0 | CM8: =CA8*CM135 -> 0 | CN8: =CB8*CN135 -> 0 | CO8: =CC8*CO135 -> 0 | CP8: =CG8+CH8+CO8 -> 0 | CS8: =CG8*CS135 -> 0 | CT8: =CH8*CT135 -> 0 | CU8: =CI8*CU135 -> 0 | CV8: =CJ8*CV135 -> 0 | CW8: =CK8*CW135 -> 0 | CX8: =CL8*CX135 -> 0 | CY8: =CM8*CY135 -> 0 | CZ8: =CN8*CZ135 -> 0 | DA8: =CO8*DA135 -> 0 | DB8: =CS8+CT8+DA8 -> 0 | DE8: =CS8*DE135 -> 0 | DF8: =CT8*DF135 -> 0 | DG8: =CU8*DG135 -> 0 | DH8: =CV8*DH135 -> 0 | DI8: =CW8*DI135 -> 0 | DJ8: =CX8*DJ135 -> 0 | DK8: =CY8*DK135 -> 0 | DL8: =CZ8*DL135 -> 0 | DM8: =DA8*DM135 -> 0 | DN8: =DE8+DF8+DM8 -> 0 | DQ8: =DE8*DQ135 -> 0 | DR8: =DF8*DR135 -> 0 | DS8: =DG8*DS135 -> 0 | DT8: =DH8*DT135 -> 0 | DU8: =DI8*DU135 -> 0 | DV8: =DJ8*DV135 -> 0 | DW8: =DK8*DW135 -> 0 | DX8: =DL8*DX135 -> 0 | DY8: =DM8*DY135 -> 0 | DZ8: =DQ8+DR8+DY8 -> 0 | EC8: =DQ8*EC135 -> 0 | ED8: =DR8*ED135 -> 0 | EE8: =DS8*EE135 -> 0 | EF8: =DT8*EF135 -> 0 | EG8: =DU8*EG135 -> 0 | EH8: =DV8*EH135 -> 0 | EI8: =DW8*EI135 -> 0 | EJ8: =DX8*EJ135 -> 0 | EK8: =DY8*EK135 -> 0 | EL8: =EC8+ED8+EK8 -> 0
A9: PAP Clôture | B9: 0 | C9: 0 | D9: 0 | E9: 0 | F9: 0 | G9: 0 | H9: 0 | I9: 0 | J9: =SUM(D9:I9) -> 0 | K9: =B9+C9+J9 -> 0 | M9: =B9*M136 -> 0 | N9: =C9*N136 -> 0 | O9: =D9*O136 -> 0 | P9: =E9*P136 -> 0 | Q9: =F9*Q136 -> 0 | R9: =G9*R136 -> 0 | S9: =H9*S136 -> 0 | T9: =I9*T136 -> 0 | U9: =SUM(O9:T9) -> 0 | V9: =M9+N9+U9 -> 0 | Y9: =M9*Y136 -> 0 | Z9: =N9*Z136 -> 0 | AA9: =O9*AA136 -> 0 | AB9: =P9*AB136 -> 0 | AC9: =Q9*AC136 -> 0 | AD9: =R9*AD136 -> 0 | AE9: =S9*AE136 -> 0 | AF9: =T9*AF136 -> 0 | AG9: =SUM(AA9:AF9) -> 0 | AH9: =Y9+Z9+AG9 -> 0 | AK9: =Y9*AK136 -> 0 | AL9: =Z9*AL136 -> 0 | AM9: =AA9*AM136 -> 0 | AN9: =AB9*AN136 -> 0 | AO9: =AC9*AO136 -> 0 | AP9: =AD9*AP136 -> 0 | AQ9: =AE9*AQ136 -> 0 | AR9: =AF9*AR136 -> 0 | AS9: =AG9*AS136 -> 0 | AT9: =AK9+AL9+AS9 -> 0 | AW9: =AK9*AW136 -> 0 | AX9: =AL9*AX136 -> 0 | AY9: =AM9*AY136 -> 0 | AZ9: =AN9*AZ136 -> 0 | BA9: =AO9*BA136 -> 0 | BB9: =AP9*BB136 -> 0 | BC9: =AQ9*BC136 -> 0 | BD9: =AR9*BD136 -> 0 | BE9: =AS9*BE136 -> 0 | BF9: =AW9+AX9+BE9 -> 0 | BI9: =AW9*BI136 -> 0 | BJ9: =AX9*BJ136 -> 0 | BK9: =AY9*BK136 -> 0 | BL9: =AZ9*BL136 -> 0 | BM9: =BA9*BM136 -> 0 | BN9: =BB9*BN136 -> 0 | BO9: =BC9*BO136 -> 0 | BP9: =BD9*BP136 -> 0 | BQ9: =BE9*BQ136 -> 0 | BR9: =BI9+BJ9+BQ9 -> 0 | BU9: =BI9*BU136 -> 0 | BV9: =BJ9*BV136 -> 0 | BW9: =BK9*BW136 -> 0 | BX9: =BL9*BX136 -> 0 | BY9: =BM9*BY136 -> 0 | BZ9: =BN9*BZ136 -> 0 | CA9: =BO9*CA136 -> 0 | CB9: =BP9*CB136 -> 0 | CC9: =BQ9*CC136 -> 0 | CD9: =BU9+BV9+CC9 -> 0 | CG9: =BU9*CG136 -> 0 | CH9: =BV9*CH136 -> 0 | CI9: =BW9*CI136 -> 0 | CJ9: =BX9*CJ136 -> 0 | CK9: =BY9*CK136 -> 0 | CL9: =BZ9*CL136 -> 0 | CM9: =CA9*CM136 -> 0 | CN9: =CB9*CN136 -> 0 | CO9: =CC9*CO136 -> 0 | CP9: =CG9+CH9+CO9 -> 0 | CS9: =CG9*CS136 -> 0 | CT9: =CH9*CT136 -> 0 | CU9: =CI9*CU136 -> 0 | CV9: =CJ9*CV136 -> 0 | CW9: =CK9*CW136 -> 0 | CX9: =CL9*CX136 -> 0 | CY9: =CM9*CY136 -> 0 | CZ9: =CN9*CZ136 -> 0 | DA9: =CO9*DA136 -> 0 | DB9: =CS9+CT9+DA9 -> 0 | DE9: =CS9*DE136 -> 0 | DF9: =CT9*DF136 -> 0 | DG9: =CU9*DG136 -> 0 | DH9: =CV9*DH136 -> 0 | DI9: =CW9*DI136 -> 0 | DJ9: =CX9*DJ136 -> 0 | DK9: =CY9*DK136 -> 0 | DL9: =CZ9*DL136 -> 0 | DM9: =DA9*DM136 -> 0 | DN9: =DE9+DF9+DM9 -> 0 | DQ9: =DE9*DQ136 -> 0 | DR9: =DF9*DR136 -> 0 | DS9: =DG9*DS136 -> 0 | DT9: =DH9*DT136 -> 0 | DU9: =DI9*DU136 -> 0 | DV9: =DJ9*DV136 -> 0 | DW9: =DK9*DW136 -> 0 | DX9: =DL9*DX136 -> 0 | DY9: =DM9*DY136 -> 0 | DZ9: =DQ9+DR9+DY9 -> 0 | EC9: =DQ9*EC136 -> 0 | ED9: =DR9*ED136 -> 0 | EE9: =DS9*EE136 -> 0 | EF9: =DT9*EF136 -> 0 | EG9: =DU9*EG136 -> 0 | EH9: =DV9*EH136 -> 0 | EI9: =DW9*EI136 -> 0 | EJ9: =DX9*EJ136 -> 0 | EK9: =DY9*EK136 -> 0 | EL9: =EC9+ED9+EK9 -> 0
A10: PANE Ouverture | B10: 1.4188283e+08 | C10: 2.8667051e+08 | D10: 9709029.5 | E10: 46246309 | F10: 1964921.2 | G10: 91870726 | H10: 6721131.9 | I10: 1.4284885e+08 | J10: =SUM(D10:I10) -> 2.9936097e+08 | K10: =B10+C10+J10 -> 7.279143e+08 | L10: ok | M10: =B11 -> 1.4188283e+08 | N10: =C11 -> 2.8667051e+08 | O10: =D11 -> 9709029.5 | P10: =E11 -> 46246309 | Q10: =F11 -> 1964921.2 | R10: =G11 -> 91870726 | S10: =H11 -> 6721131.9 | T10: =I11 -> 1.4284885e+08 | U10: =SUM(O10:T10) -> 2.9936097e+08 | V10: =M10+N10+U10 -> 7.279143e+08 | W10: =V10=K10 -> TRUE | Y10: =M10 -> 1.4188283e+08 | Z10: =N10 -> 2.8667051e+08 | AA10: =O10 -> 9709029.5 | AB10: =P10 -> 46246309 | AC10: =Q10 -> 1964921.2 | AD10: =R10 -> 91870726 | AE10: =S10 -> 6721131.9 | AF10: =T10 -> 1.4284885e+08 | AG10: =SUM(AA10:AF10) -> 2.9936097e+08 | AH10: =Y10+Z10+AG10 -> 7.279143e+08 | AI10: =AH10=V10 -> TRUE | AK10: =Y11*AK137 -> 1.4188283e+08 | AL10: =Z11*AL137 -> 2.8667051e+08 | AM10: =AA11*AM137 -> 9709029.5 | AN10: =AB11*AN137 -> 46246309 | AO10: =AC11*AO137 -> 1964921.2 | AP10: =AD11*AP137 -> 91870726 | AQ10: =AE11*AQ137 -> 6721131.9 | AR10: =AF11*AR137 -> 1.4284885e+08 | AS10: =SUM(AM10:AR10) -> 2.9936097e+08 | AT10: =AK10+AL10+AS10 -> 7.279143e+08 | AU10: =AT10=AH10 -> TRUE | AW10: =AK11*AW137 -> 1.4188283e+08 | AX10: =AL11*AX137 -> 2.8667051e+08 | AY10: =AM11*AY137 -> 9709029.5 | AZ10: =AN11*AZ137 -> 46246309 | BA10: =AO11*BA137 -> 1964921.2 | BB10: =AP11*BB137 -> 91870726 | BC10: =AQ11*BC137 -> 6721131.9 | BD10: =AR11*BD137 -> 1.4284885e+08 | BE10: =SUM(AY10:BD10) -> 2.9936097e+08 | BF10: =AW10+AX10+BE10 -> 7.279143e+08 | BG10: =BF10=AW10 -> FALSE | BI10: =AW11*BI137 -> 1.4188283e+08 | BJ10: =AX11*BJ137 -> 2.8667051e+08 | BK10: =AY11*BK137 -> 9709029.5 | BL10: =AZ11*BL137 -> 46246309 | BM10: =BA11*BM137 -> 1964921.2 | BN10: =BB11*BN137 -> 91870726 | BO10: =BC11*BO137 -> 6721131.9 | BP10: =BD11*BP137 -> 1.4284885e+08 | BQ10: =SUM(BK10:BP10) -> 2.9936097e+08 | BR10: =BI10+BJ10+BQ10 -> 7.279143e+08 | BU10: =BI11*BU137 -> 1.4188283e+08 | BV10: =BJ11*BV137 -> 2.8667051e+08 | BW10: =BK11*BW137 -> 9709029.5 | BX10: =BL11*BX137 -> 46246309 | BY10: =BM11*BY137 -> 1964921.2 | BZ10: =BN11*BZ137 -> 91870726 | CA10: =BO11*CA137 -> 6721131.9 | CB10: =BP11*CB137 -> 1.4284885e+08 | CC10: =SUM(BW10:CB10) -> 2.9936097e+08 | CD10: =BU10+BV10+CC10 -> 7.279143e+08 | CE10: =CD10=BU10 -> FALSE | CG10: =BU11*CG137 -> 1.4188283e+08 | CH10: =BV11*CH137 -> 2.8667051e+08 | CI10: =BW11*CI137 -> 9709029.5 | CJ10: =BX11*CJ137 -> 46246309 | CK10: =BY11*CK137 -> 1964921.2 | CL10: =BZ11*CL137 -> 91870726 | CM10: =CA11*CM137 -> 6721131.9 | CN10: =CB11*CN137 -> 1.4284885e+08 | CO10: =SUM(CI10:CN10) -> 2.9936097e+08 | CP10: =CG10+CH10+CO10 -> 7.279143e+08 | CS10: =CG11*CS137 -> 1.4188283e+08 | CT10: =CH11*CT137 -> 2.8667051e+08 | CU10: =CI11*CU137 -> 9709029.5 | CV10: =CJ11*CV137 -> 46246309 | CW10: =CK11*CW137 -> 1964921.2 | CX10: =CL11*CX137 -> 91870726 | CY10: =CM11*CY137 -> 6721131.9 | CZ10: =CN11*CZ137 -> 1.4284885e+08 | DA10: =SUM(CU10:CZ10) -> 2.9936097e+08 | DB10: =CS10+CT10+DA10 -> 7.279143e+08 | DE10: =CS11*DE137 -> 1.4188283e+08 | DF10: =CT11*DF137 -> 2.8667051e+08 | DG10: =CU11*DG137 -> 9709029.5 | DH10: =CV11*DH137 -> 46246309 | DI10: =CW11*DI137 -> 1964921.2 | DJ10: =CX11*DJ137 -> 91870726 | DK10: =CY11*DK137 -> 6721131.9 | DL10: =CZ11*DL137 -> 1.4284885e+08 | DM10: =SUM(DG10:DL10) -> 2.9936097e+08 | DN10: =DE10+DF10+DM10 -> 7.279143e+08 | DQ10: =DE11*DQ137 -> 1.4188283e+08 | DR10: =DF11*DR137 -> 2.8667051e+08 | DS10: =DG11*DS137 -> 9709029.5 | DT10: =DH11*DT137 -> 46246309 | DU10: =DI11*DU137 -> 1964921.2 | DV10: =DJ11*DV137 -> 91870726 | DW10: =DK11*DW137 -> 6721131.9 | DX10: =DL11*DX137 -> 1.4284885e+08 | DY10: =SUM(DS10:DX10) -> 2.9936097e+08 | DZ10: =DQ10+DR10+DY10 -> 7.279143e+08 | EC10: =DQ11*EC137 -> 1.4188283e+08 | ED10: =DR11*ED137 -> 2.8667051e+08 | EE10: =DS11*EE137 -> 9709029.5 | EF10: =DT11*EF137 -> 46246309 | EG10: =DU11*EG137 -> 1964921.2 | EH10: =DV11*EH137 -> 91870726 | EI10: =DW11*EI137 -> 6721131.9 | EJ10: =DX11*EJ137 -> 1.4284885e+08 | EK10: =SUM(EE10:EJ10) -> 2.9936097e+08 | EL10: =EC10+ED10+EK10 -> 7.279143e+08
A11: PANE Clôture | B11: =B10 -> 1.4188283e+08 | C11: =C10 -> 2.8667051e+08 | D11: =D10 -> 9709029.5 | E11: =E10 -> 46246309 | F11: =F10 -> 1964921.2 | G11: =G10 -> 91870726 | H11: =H10 -> 6721131.9 | I11: =I10 -> 1.4284885e+08 | J11: =SUM(D11:I11) -> 2.9936097e+08 | K11: =B11+C11+J11 -> 7.279143e+08 | L11: ok | M11: =M10 -> 1.4188283e+08 | N11: =N10 -> 2.8667051e+08 | O11: =O10 -> 9709029.5 | P11: =P10 -> 46246309 | Q11: =Q10 -> 1964921.2 | R11: =R10 -> 91870726 | S11: =S10 -> 6721131.9 | T11: =T10 -> 1.4284885e+08 | U11: =SUM(O11:T11) -> 2.9936097e+08 | V11: =M11+N11+U11 -> 7.279143e+08 | W11: =V11=K11 -> TRUE | Y11: =M11 -> 1.4188283e+08 | Z11: =N11*Z138 -> 2.8667051e+08 | AA11: =O11*AA138 -> 9709029.5 | AB11: =P11*AB138 -> 46246309 | AC11: =Q11*AC138 -> 1964921.2 | AD11: =R11*AD138 -> 91870726 | AE11: =S11*AE138 -> 6721131.9 | AF11: =T11*AF138 -> 1.4284885e+08 | AG11: =SUM(AA11:AF11) -> 2.9936097e+08 | AH11: =Y11+Z11+AG11 -> 7.279143e+08 | AI11: =AH11=V11 -> TRUE | AK11: =Y11*AK138 -> 1.4188283e+08 | AL11: =Z11*AL138 -> 2.8667051e+08 | AM11: =AA11*AM138 -> 9709029.5 | AN11: =AB11*AN138 -> 46246309 | AO11: =AC11*AO138 -> 1964921.2 | AP11: =AD11*AP138 -> 91870726 | AQ11: =AE11*AQ138 -> 6721131.9 | AR11: =AF11*AR138 -> 1.4284885e+08 | AS11: =SUM(AM11:AR11) -> 2.9936097e+08 | AT11: =AK11+AL11+AS11 -> 7.279143e+08 | AU11: =AT11=AH11 -> TRUE | AW11: =AK11*AW138 -> 1.4188283e+08 | AX11: =AL11*AX138 -> 2.8667051e+08 | AY11: =AM11*AY138 -> 9709029.5 | AZ11: =AN11*AZ138 -> 46246309 | BA11: =AO11*BA138 -> 1964921.2 | BB11: =AP11*BB138 -> 91870726 | BC11: =AQ11*BC138 -> 6721131.9 | BD11: =AR11*BD138 -> 1.4284885e+08 | BE11: =SUM(AY11:BD11) -> 2.9936097e+08 | BF11: =AW11+AX11+BE11 -> 7.279143e+08 | BG11: =BF11=AW11 -> FALSE | BI11: =AW11*BI138 -> 1.4188283e+08 | BJ11: =AX11*BJ138 -> 2.8667051e+08 | BK11: =AY11*BK138 -> 9709029.5 | BL11: =AZ11*BL138 -> 46246309 | BM11: =BA11*BM138 -> 1964921.2 | BN11: =BB11*BN138 -> 91870726 | BO11: =BC11*BO138 -> 6721131.9 | BP11: =BD11*BP138 -> 1.4284885e+08 | BQ11: =SUM(BK11:BP11) -> 2.9936097e+08 | BR11: =BI11+BJ11+BQ11 -> 7.279143e+08 | BU11: =BI11*BU138 -> 1.4188283e+08 | BV11: =BJ11*BV138 -> 2.8667051e+08 | BW11: =BK11*BW138 -> 9709029.5 | BX11: =BL11*BX138 -> 46246309 | BY11: =BM11*BY138 -> 1964921.2 | BZ11: =BN11*BZ138 -> 91870726 | CA11: =BO11*CA138 -> 6721131.9 | CB11: =BP11*CB138 -> 1.4284885e+08 | CC11: =SUM(BW11:CB11) -> 2.9936097e+08 | CD11: =BU11+BV11+CC11 -> 7.279143e+08 | CE11: =CD11=BU11 -> FALSE | CG11: =BU11*CG138 -> 1.4188283e+08 | CH11: =BV11*CH138 -> 2.8667051e+08 | CI11: =BW11*CI138 -> 9709029.5 | CJ11: =BX11*CJ138 -> 46246309 | CK11: =BY11*CK138 -> 1964921.2 | CL11: =BZ11*CL138 -> 91870726 | CM11: =CA11*CM138 -> 6721131.9 | CN11: =CB11*CN138 -> 1.4284885e+08 | CO11: =SUM(CI11:CN11) -> 2.9936097e+08 | CP11: =CG11+CH11+CO11 -> 7.279143e+08 | CS11: =CG11*CS138 -> 1.4188283e+08 | CT11: =CH11*CT138 -> 2.8667051e+08 | CU11: =CI11*CU138 -> 9709029.5 | CV11: =CJ11*CV138 -> 46246309 | CW11: =CK11*CW138 -> 1964921.2 | CX11: =CL11*CX138 -> 91870726 | CY11: =CM11*CY138 -> 6721131.9 | CZ11: =CN11*CZ138 -> 1.4284885e+08 | DA11: =SUM(CU11:CZ11) -> 2.9936097e+08 | DB11: =CS11+CT11+DA11 -> 7.279143e+08 | DE11: =CS11*DE138 -> 1.4188283e+08 | DF11: =CT11*DF138 -> 2.8667051e+08 | DG11: =CU11*DG138 -> 9709029.5 | DH11: =CV11*DH138 -> 46246309 | DI11: =CW11*DI138 -> 1964921.2 | DJ11: =CX11*DJ138 -> 91870726 | DK11: =CY11*DK138 -> 6721131.9 | DL11: =CZ11*DL138 -> 1.4284885e+08 | DM11: =SUM(DG11:DL11) -> 2.9936097e+08 | DN11: =DE11+DF11+DM11 -> 7.279143e+08 | DQ11: =DE11*DQ138 -> 1.4188283e+08 | DR11: =DF11*DR138 -> 2.8667051e+08 | DS11: =DG11*DS138 -> 9709029.5 | DT11: =DH11*DT138 -> 46246309 | DU11: =DI11*DU138 -> 1964921.2 | DV11: =DJ11*DV138 -> 91870726 | DW11: =DK11*DW138 -> 6721131.9 | DX11: =DL11*DX138 -> 1.4284885e+08 | DY11: =SUM(DS11:DX11) -> 2.9936097e+08 | DZ11: =DQ11+DR11+DY11 -> 7.279143e+08 | EC11: 1.4897697e+08 | ED11: 3.0100404e+08 | EE11: 10194481 | EF11: 48558624 | EG11: 2063167.3 | EH11: 96464262 | EI11: 7057188.5 | EJ11: 1.4999129e+08 | EK11: =SUM(EE11:EJ11) -> 3.1432902e+08 | EL11: =EC11+ED11+EK11 -> 7.6431002e+08
A12: Chiffre d'Affaire | B12: =B7-B8+B9-B10+B11 -> 2.0666856e+09 | C12: =C7-C8+C9-C10+C11 -> 1.8778018e+09 | D12: =D7-D8+D9-D10+D11 -> 10053583 | E12: =E7-E8+E9-E10+E11 -> 8.9002401e+08 | F12: =F7-F8+F9-F10+F11 -> 1.2721586e+08 | G12: =G7-G8+G9-G10+G11 -> 27995224 | H12: =H7-H8+H9-H10+H11 -> 7.0638702e+08 | I12: =I7-I8+I9-I10+I11 -> 20050105 | ... K12: =K7-K8+K9-K10+K11 -> 5.7262132e+09 | M12: =M7-M8+M9-M10+M11 -> 2.5488992e+09 | N12: =N7-N8+N9-N10+N11 -> 2.1955344e+09 | O12: =O7-O8+O9-O10+O11 -> 29287346 | P12: =P7-P8+P9-P10+P11 -> 2.7677022e+09 | Q12: =Q7-Q8+Q9-Q10+Q11 -> 3.2537641e+08 | R12: =R7-R8+R9-R10+R11 -> 1.4841429e+08 | S12: =S7-S8+S9-S10+S11 -> 9.7934139e+08 | T12: =T7-T8+T9-T10+T11 -> 1.2327826e+09 | ... V12: =V7-V8+V9-V10+V11 -> 1.0227338e+10 | Y12: =Y7-Y8+Y9-Y10+Y11 -> 3.0333946e+09 | Z12: =Z7-Z8+Z9-Z10+Z11 -> 2.5452707e+09 | AA12: =AA7-AA8+AA9-AA10+AA11 -> 30127265 | AB12: =AB7-AB8+AB9-AB10+AB11 -> 4.6432515e+09 | AC12: =AC7-AC8+AC9-AC10+AC11 -> 4.2712564e+08 | AD12: =AD7-AD8+AD9-AD10+AD11 -> 1.6890644e+08 | AE12: =AE7-AE8+AE9-AE10+AE11 -> 1.1984575e+09 | AF12: =AF7-AF8+AF9-AF10+AF11 -> 1.3509593e+09 | ... AH12: =AH7-AH8+AH9-AH10+AH11 -> 1.3397493e+10 | AK12: =AK7-AK8+AK9-AK10+AK11 -> 3.2600989e+09 | AL12: =AL7-AL8+AL9-AL10+AL11 -> 2.7548907e+09 | AM12: =AM7-AM8+AM9-AM10+AM11 -> 41721466 | AN12: =AN7-AN8+AN9-AN10+AN11 -> 6.1361385e+09 | AO12: =AO7-AO8+AO9-AO10+AO11 -> 5.276631e+08 | AP12: =AP7-AP8+AP9-AP10+AP11 -> 4.9485857e+08 | AQ12: =AQ7-AQ8+AQ9-AQ10+AQ11 -> 1.3787138e+09 | AR12: =AR7-AR8+AR9-AR10+AR11 -> 1.3675495e+09 | ... AT12: =AT7-AT8+AT9-AT10+AT11 -> 1.5961634e+10 | AW12: =AW7-AW8+AW9-AW10+AW11 -> 4.3775806e+09 | AX12: =AX7-AX8+AX9-AX10+AX11 -> 3.1809995e+09 | AY12: =AY7-AY8+AY9-AY10+AY11 -> 56771021 | AZ12: =AZ7-AZ8+AZ9-AZ10+AZ11 -> 6.5221974e+09 | BA12: =BA7-BA8+BA9-BA10+BA11 -> 6.5236958e+08 | BB12: =BB7-BB8+BB9-BB10+BB11 -> 5.8494767e+08 | BC12: =BC7-BC8+BC9-BC10+BC11 -> 1.5971969e+09 | BD12: =BD7-BD8+BD9-BD10+BD11 -> 1.849841e+09 | ... BF12: =BF7-BF8+BF9-BF10+BF11 -> 1.8821904e+10 | BI12: =BI7-BI8+BI9-BI10+BI11 -> 4.7250519e+09 | BJ12: =BJ7-BJ8+BJ9-BJ10+BJ11 -> 3.3125841e+09 | BK12: =BK7-BK8+BK9-BK10+BK11 -> 71065615 | BL12: =BL7-BL8+BL9-BL10+BL11 -> 7.5111084e+09 | BM12: =BM7-BM8+BM9-BM10+BM11 -> 6.6439984e+08 | BN12: =BN7-BN8+BN9-BN10+BN11 -> 6.2043728e+08 | BO12: =BO7-BO8+BO9-BO10+BO11 -> 1.6774132e+09 | BP12: =BP7-BP8+BP9-BP10+BP11 -> 1.9679284e+09 | ... BR12: =BR7-BR8+BR9-BR10+BR11 -> 2.0549989e+10 | BU12: =BU7-BU8+BU9-BU10+BU11 -> 5.0426794e+09 | BV12: =BV7-BV8+BV9-BV10+BV11 -> 3.507341e+09 | BW12: =BW7-BW8+BW9-BW10+BW11 -> 75735154 | BX12: =BX7-BX8+BX9-BX10+BX11 -> 7.6256043e+09 | BY12: =BY7-BY8+BY9-BY10+BY11 -> 7.0489351e+08 | BZ12: =BZ7-BZ8+BZ9-BZ10+BZ11 -> 6.5144005e+08 | CA12: =CA7-CA8+CA9-CA10+CA11 -> 1.7500469e+09 | CB12: =CB7-CB8+CB9-CB10+CB11 -> 2.0924516e+09 | ... CD12: =CD7-CD8+CD9-CD10+CD11 -> 2.1450192e+10 | CG12: =CG7-CG8+CG9-CG10+CG11 -> 5.8325733e+09 | CH12: =CH7-CH8+CH9-CH10+CH11 -> 3.687902e+09 | CI12: =CI7-CI8+CI9-CI10+CI11 -> 76186845 | CJ12: =CJ7-CJ8+CJ9-CJ10+CJ11 -> 7.7515327e+09 | CK12: =CK7-CK8+CK9-CK10+CK11 -> 8.0873244e+08 | CL12: =CL7-CL8+CL9-CL10+CL11 -> 1.7272506e+09 | CM12: =CM7-CM8+CM9-CM10+CM11 -> 1.8142738e+09 | CN12: =CN7-CN8+CN9-CN10+CN11 -> 2.1959177e+09 | ... CP12: =CP7-CP8+CP9-CP10+CP11 -> 2.3894369e+10 | CS12: =CS7-CS8+CS9-CS10+CS11 -> 6.1868053e+09 | CT12: =CT7-CT8+CT9-CT10+CT11 -> 3.8589292e+09 | CU12: =CU7-CU8+CU9-CU10+CU11 -> 78104401 | CV12: =CV7-CV8+CV9-CV10+CV11 -> 8.2211768e+09 | CW12: =CW7-CW8+CW9-CW10+CW11 -> 8.1306214e+08 | CX12: =CX7-CX8+CX9-CX10+CX11 -> 2.0575038e+09 | CY12: =CY7-CY8+CY9-CY10+CY11 -> 1.8676955e+09 | CZ12: =CZ7-CZ8+CZ9-CZ10+CZ11 -> 2.3585336e+09 | ... DB12: =DB7-DB8+DB9-DB10+DB11 -> 2.5441811e+10 | DE12: =DE7-DE8+DE9-DE10+DE11 -> 6.6191466e+09 | DF12: =DF7-DF8+DF9-DF10+DF11 -> 4.1293042e+09 | DG12: =DG7-DG8+DG9-DG10+DG11 -> 81844041 | DH12: =DH7-DH8+DH9-DH10+DH11 -> 8.5702584e+09 | DI12: =DI7-DI8+DI9-DI10+DI11 -> 8.2413417e+08 | DJ12: =DJ7-DJ8+DJ9-DJ10+DJ11 -> 2.0938713e+09 | DK12: =DK7-DK8+DK9-DK10+DK11 -> 2.0055889e+09 | DL12: =DL7-DL8+DL9-DL10+DL11 -> 2.5246336e+09 | ... DN12: =DN7-DN8+DN9-DN10+DN11 -> 2.6848781e+10 | DQ12: =DQ7-DQ8+DQ9-DQ10+DQ11 -> 7.0399024e+09 | DR12: =DR7-DR8+DR9-DR10+DR11 -> 4.3226175e+09 | DS12: =DS7-DS8+DS9-DS10+DS11 -> 84926760 | DT12: =DT7-DT8+DT9-DT10+DT11 -> 8.7111604e+09 | DU12: =DU7-DU8+DU9-DU10+DU11 -> 8.6915286e+08 | DV12: =DV7-DV8+DV9-DV10+DV11 -> 2.1725233e+09 | DW12: =DW7-DW8+DW9-DW10+DW11 -> 2.3526152e+09 | DX12: =DX7-DX8+DX9-DX10+DX11 -> 2.7555055e+09 | ... DZ12: =DZ7-DZ8+DZ9-DZ10+DZ11 -> 2.8308404e+10 | EC12: =EC7-EC8+EC9-EC10+EC11 -> 7.3702022e+09 | ED12: =ED7-ED8+ED9-ED10+ED11 -> 4.3912073e+09 | EE12: =EE7-EE8+EE9-EE10+EE11 -> 91440861 | EF12: =EF7-EF8+EF9-EF10+EF11 -> 8.9314915e+09 | EG12: =EG7-EG8+EG9-EG10+EG11 -> 9.3121548e+08 | EH12: =EH7-EH8+EH9-EH10+EH11 -> 2.2205583e+09 | EI12: =EI7-EI8+EI9-EI10+EI11 -> 2.4294493e+09 | EJ12: =EJ7-EJ8+EJ9-EJ10+EJ11 -> 2.8563756e+09 | ... EL12: =EL7-EL8+EL9-EL10+EL11 -> 2.9221941e+10
A14: Sinistres payés Per. | B14: ='Hyp 2027'!B264 -> 2.8513607e+08 | C14: ='Hyp 2027'!C264 -> 2.490522e+08 | D14: ='Hyp 2027'!D264 -> 1521445.7 | E14: ='Hyp 2027'!E264 -> 4.2015486e+08 | F14: ='Hyp 2027'!F264 -> 9177868.9 | G14: ='Hyp 2027'!G264 -> 37725355 | H14: ='Hyp 2027'!H264 -> 46900845 | I14: ='Hyp 2027'!I264 -> 78664185 | J14: =SUM(D14:I14) -> 5.9414456e+08 | K14: =B14+C14+J14 -> 1.1283328e+09 | M14: =B14+'Hyp 2027'!B265 -> 5.7027214e+08 | N14: =C14+'Hyp 2027'!C265 -> 4.981044e+08 | O14: =D14+'Hyp 2027'!D265 -> 3042891.4 | P14: =E14+'Hyp 2027'!E265 -> 8.4030972e+08 | Q14: =F14+'Hyp 2027'!F265 -> 18355738 | R14: =G14+'Hyp 2027'!G265 -> 75450710 | S14: =H14+'Hyp 2027'!H265 -> 93801691 | T14: =I14+'Hyp 2027'!I265 -> 1.5732837e+08 | U14: =SUM(O14:T14) -> 1.1882891e+09 | V14: =M14+N14+U14 -> 2.2566657e+09 | Y14: =M14+'Hyp 2027'!B265 -> 8.5540821e+08 | Z14: =N14+'Hyp 2027'!C265 -> 7.4715661e+08 | AA14: =O14+'Hyp 2027'!D265 -> 4564337.1 | AB14: =P14+'Hyp 2027'!E265 -> 1.2604646e+09 | AC14: =Q14+'Hyp 2027'!F265 -> 27533607 | AD14: =R14+'Hyp 2027'!G265 -> 1.1317607e+08 | AE14: =S14+'Hyp 2027'!H265 -> 1.4070254e+08 | AF14: =T14+'Hyp 2027'!I265 -> 2.3599255e+08 | AG14: =SUM(AA14:AF14) -> 1.7824337e+09 | AH14: =Y14+Z14+AG14 -> 3.3849985e+09 | AK14: =Y14+'Hyp 2027'!B265 -> 1.1405443e+09 | AL14: =Z14+'Hyp 2027'!C265 -> 9.9620881e+08 | AM14: =AA14+'Hyp 2027'!D265 -> 6085782.9 | AN14: =AB14+'Hyp 2027'!E265 -> 1.6806194e+09 | AO14: =AC14+'Hyp 2027'!F265 -> 36711476 | AP14: =AD14+'Hyp 2027'!G265 -> 1.5090142e+08 | AQ14: =AE14+'Hyp 2027'!H265 -> 1.8760338e+08 | AR14: =AF14+'Hyp 2027'!I265 -> 3.1465674e+08 | AS14: =SUM(AM14:AR14) -> 2.3765782e+09 | AT14: =AK14+AL14+AS14 -> 4.5133313e+09 | AW14: =AK14+'Hyp 2027'!B265 -> 1.4256803e+09 | AX14: =AL14+'Hyp 2027'!C265 -> 1.245261e+09 | AY14: =AM14+'Hyp 2027'!D265 -> 7607228.6 | AZ14: =AN14+'Hyp 2027'!E265 -> 2.1007743e+09 | BA14: =AO14+'Hyp 2027'!F265 -> 45889345 | BB14: =AP14+'Hyp 2027'!G265 -> 1.8862678e+08 | BC14: =AQ14+'Hyp 2027'!H265 -> 2.3450423e+08 | BD14: =AR14+'Hyp 2027'!I265 -> 3.9332092e+08 | BE14: =SUM(AY14:BD14) -> 2.9707228e+09 | BF14: =AW14+AX14+BE14 -> 5.6416642e+09 | BI14: =AW14+'Hyp 2027'!B265 -> 1.7108164e+09 | BJ14: =AX14+'Hyp 2027'!C265 -> 1.4943132e+09 | BK14: =AY14+'Hyp 2027'!D265 -> 9128674.3 | BL14: =AZ14+'Hyp 2027'!E265 -> 2.5209292e+09 | BM14: =BA14+'Hyp 2027'!F265 -> 55067214 | BN14: =BB14+'Hyp 2027'!G265 -> 2.2635213e+08 | BO14: =BC14+'Hyp 2027'!H265 -> 2.8140507e+08 | BP14: =BD14+'Hyp 2027'!I265 -> 4.7198511e+08 | BQ14: =SUM(BK14:BP14) -> 3.5648674e+09 | BR14: =BI14+BJ14+BQ14 -> 6.769997e+09 | BU14: =BI14+'Hyp 2027'!B265 -> 1.9959525e+09 | BV14: =BJ14+'Hyp 2027'!C265 -> 1.7433654e+09 | BW14: =BK14+'Hyp 2027'!D265 -> 10650120 | BX14: =BL14+'Hyp 2027'!E265 -> 2.941084e+09 | BY14: =BM14+'Hyp 2027'!F265 -> 64245083 | BZ14: =BN14+'Hyp 2027'!G265 -> 2.6407749e+08 | CA14: =BO14+'Hyp 2027'!H265 -> 3.2830592e+08 | CB14: =BP14+'Hyp 2027'!I265 -> 5.5064929e+08 | CC14: =SUM(BW14:CB14) -> 4.1590119e+09 | CD14: =BU14+BV14+CC14 -> 7.8983298e+09 | CG14: =BU14+'Hyp 2027'!B265 -> 2.2810886e+09 | CH14: =BV14+'Hyp 2027'!C265 -> 1.9924176e+09 | CI14: =BW14+'Hyp 2027'!D265 -> 12171566 | CJ14: =BX14+'Hyp 2027'!E265 -> 3.3612389e+09 | CK14: =BY14+'Hyp 2027'!F265 -> 73422952 | CL14: =BZ14+'Hyp 2027'!G265 -> 3.0180284e+08 | CM14: =CA14+'Hyp 2027'!H265 -> 3.7520676e+08 | CN14: =CB14+'Hyp 2027'!I265 -> 6.2931348e+08 | CO14: =SUM(CI14:CN14) -> 4.7531565e+09 | CP14: =CG14+CH14+CO14 -> 9.0266627e+09 | CS14: =CG14+'Hyp 2027'!B265 -> 2.5662246e+09 | CT14: =CH14+'Hyp 2027'!C265 -> 2.2414698e+09 | CU14: =CI14+'Hyp 2027'!D265 -> 13693011 | CV14: =CJ14+'Hyp 2027'!E265 -> 3.7813938e+09 | CW14: =CK14+'Hyp 2027'!F265 -> 82600821 | CX14: =CL14+'Hyp 2027'!G265 -> 3.395282e+08 | CY14: =CM14+'Hyp 2027'!H265 -> 4.2210761e+08 | CZ14: =CN14+'Hyp 2027'!I265 -> 7.0797766e+08 | DA14: =SUM(CU14:CZ14) -> 5.3473011e+09 | DB14: =CS14+CT14+DA14 -> 1.0154995e+10 | DE14: =CS14+'Hyp 2027'!B265 -> 2.8513607e+09 | DF14: =CT14+'Hyp 2027'!C265 -> 2.490522e+09 | DG14: =CU14+'Hyp 2027'!D265 -> 15214457 | DH14: =CV14+'Hyp 2027'!E265 -> 4.2015486e+09 | DI14: =CW14+'Hyp 2027'!F265 -> 91778689 | DJ14: =CX14+'Hyp 2027'!G265 -> 3.7725355e+08 | DK14: =CY14+'Hyp 2027'!H265 -> 4.6900845e+08 | DL14: =CZ14+'Hyp 2027'!I265 -> 7.8664185e+08 | DM14: =DA14*(1+'Hyp 2027'!J265) -> 6.0335354e+18 | DN14: =DE14+DF14+DM14 -> 6.0335354e+18 | DQ14: =DE14+'Hyp 2027'!B265 -> 3.1364968e+09 | DR14: =DF14+'Hyp 2027'!C265 -> 2.7395742e+09 | DS14: =DG14+'Hyp 2027'!D265 -> 16735903 | DT14: =DH14+'Hyp 2027'!E265 -> 4.6217035e+09 | DU14: =DI14+'Hyp 2027'!F265 -> 1.0095656e+08 | DV14: =DJ14+'Hyp 2027'!G265 -> 4.1497891e+08 | DW14: =DK14+'Hyp 2027'!H265 -> 5.159093e+08 | DX14: =DL14+'Hyp 2027'!I265 -> 8.6530603e+08 | DY14: =SUM(DS14:DX14) -> 6.5355902e+09 | DZ14: =DQ14+DR14+DY14 -> 1.2411661e+10 | EC14: =DQ14+'Hyp 2027'!B265 -> 3.4216328e+09 | ED14: =DR14+'Hyp 2027'!C265 -> 2.9886264e+09 | EE14: =DS14+'Hyp 2027'!D265 -> 18257349 | EF14: =DT14+'Hyp 2027'!E265 -> 5.0418583e+09 | EG14: =DU14+'Hyp 2027'!F265 -> 1.1013443e+08 | EH14: =DV14+'Hyp 2027'!G265 -> 4.5270426e+08 | EI14: =DW14+'Hyp 2027'!H265 -> 5.6281014e+08 | EJ14: =DX14+'Hyp 2027'!I265 -> 9.4397021e+08 | EK14: =SUM(EE14:EJ14) -> 7.1297347e+09 | EL14: =EC14+ED14+EK14 -> 1.3539994e+10
A15: Sinistres payés Ant. | J15: =SUM(D15:I15) -> 0 | K15: =B15+C15+J15 -> 0 | M15: =B15*(1+M$118) -> 0 | N15: =C15*(1+N$118) -> 0 | O15: =D15*(1+O$118) -> 0 | P15: =E15*(1+P$118) -> 0 | Q15: =F15*(1+Q$118) -> 0 | R15: =G15*(1+R$118) -> 0 | S15: =H15*(1+S$118) -> 0 | T15: =I15*(1+T$118) -> 0 | U15: =SUM(O15:T15) -> 0 | V15: =M15+N15+U15 -> 0 | AG15: =SUM(AA15:AF15) -> 0 | AH15: =Y15+Z15+AG15 -> 0 | AS15: =SUM(AM15:AR15) -> 0 | AT15: =AK15+AL15+AS15 -> 0 | BE15: =SUM(AY15:BD15) -> 0 | BF15: =AW15+AX15+BE15 -> 0 | BQ15: =SUM(BK15:BP15) -> 0 | BR15: =BI15+BJ15+BQ15 -> 0 | CC15: =SUM(BW15:CB15) -> 0 | CD15: =BU15+BV15+CC15 -> 0 | CG15: =BU15*CG140 -> 0 | CH15: =BV15*CH140 -> 0 | CI15: =BW15*CI140 -> 0 | CJ15: =BX15*CJ140 -> 0 | CK15: =BY15*CK140 -> 0 | CL15: =BZ15*CL140 -> 0 | CM15: =CA15*CM140 -> 0 | CN15: =CB15*CN140 -> 0 | CO15: =SUM(CI15:CN15) -> 0 | CP15: =CG15+CH15+CO15 -> 0 | CS15: =CG15*CS140 -> 0 | CT15: =CH15*CT140 -> 0 | CU15: =CI15*CU140 -> 0 | CV15: =CJ15*CV140 -> 0 | CW15: =CK15*CW140 -> 0 | CX15: =CL15*CX140 -> 0 | CY15: =CM15*CY140 -> 0 | CZ15: =CN15*CZ140 -> 0 | DA15: =SUM(CU15:CZ15) -> 0 | DB15: =CS15+CT15+DA15 -> 0 | DE15: =CS15*DE140 -> 0 | DF15: =CT15*DF140 -> 0 | DG15: =CU15*DG140 -> 0 | DH15: =CV15*DH140 -> 0 | DI15: =CW15*DI140 -> 0 | DJ15: =CX15*DJ140 -> 0 | DK15: =CY15*DK140 -> 0 | DL15: =CZ15*DL140 -> 0 | DM15: =SUM(DG15:DL15) -> 0 | DN15: =DE15+DF15+DM15 -> 0 | DQ15: =DE15*DQ140 -> 0 | DR15: =DF15*DR140 -> 0 | DS15: =DG15*DS140 -> 0 | DT15: =DH15*DT140 -> 0 | DU15: =DI15*DU140 -> 0 | DV15: =DJ15*DV140 -> 0 | DW15: =DK15*DW140 -> 0 | DX15: =DL15*DX140 -> 0 | DY15: =SUM(DS15:DX15) -> 0 | DZ15: =DQ15+DR15+DY15 -> 0 | EC15: =DQ15*EC140 -> 0 | ED15: =DR15*ED140 -> 0 | EE15: =DS15*EE140 -> 0 | EF15: =DT15*EF140 -> 0 | EG15: =DU15*EG140 -> 0 | EH15: =DV15*EH140 -> 0 | EI15: =DW15*EI140 -> 0 | EJ15: =DX15*EJ140 -> 0 | EK15: =SUM(EE15:EJ15) -> 0 | EL15: =EC15+ED15+EK15 -> 0
A16: Sinistres Payés net des recours | B16: =B14+B15 -> 2.8513607e+08 | C16: =C14+C15 -> 2.490522e+08 | D16: =D14+D15 -> 1521445.7 | E16: =E14+E15 -> 4.2015486e+08 | F16: =F14+F15 -> 9177868.9 | G16: =G14+G15 -> 37725355 | H16: =H14+H15 -> 46900845 | I16: =I14+I15 -> 78664185 | ... K16: =K14+K15 -> 1.1283328e+09 | M16: =M14+M15 -> 5.7027214e+08 | N16: =N14+N15 -> 4.981044e+08 | O16: =O14+O15 -> 3042891.4 | P16: =P14+P15 -> 8.4030972e+08 | Q16: =Q14+Q15 -> 18355738 | R16: =R14+R15 -> 75450710 | S16: =S14+S15 -> 93801691 | T16: =T14+T15 -> 1.5732837e+08 | ... V16: =V14+V15 -> 2.2566657e+09 | Y16: =Y14+Y15 -> 8.5540821e+08 | Z16: =Z14+Z15 -> 7.4715661e+08 | AA16: =AA14+AA15 -> 4564337.1 | AB16: =AB14+AB15 -> 1.2604646e+09 | AC16: =AC14+AC15 -> 27533607 | AD16: =AD14+AD15 -> 1.1317607e+08 | AE16: =AE14+AE15 -> 1.4070254e+08 | AF16: =AF14+AF15 -> 2.3599255e+08 | ... AH16: =AH14+AH15 -> 3.3849985e+09 | AK16: =AK14+AK15 -> 1.1405443e+09 | AL16: =AL14+AL15 -> 9.9620881e+08 | AM16: =AM14+AM15 -> 6085782.9 | AN16: =AN14+AN15 -> 1.6806194e+09 | AO16: =AO14+AO15 -> 36711476 | AP16: =AP14+AP15 -> 1.5090142e+08 | AQ16: =AQ14+AQ15 -> 1.8760338e+08 | AR16: =AR14+AR15 -> 3.1465674e+08 | ... AT16: =AT14+AT15 -> 4.5133313e+09 | AW16: =AW14+AW15 -> 1.4256803e+09 | AX16: =AX14+AX15 -> 1.245261e+09 | AY16: =AY14+AY15 -> 7607228.6 | AZ16: =AZ14+AZ15 -> 2.1007743e+09 | BA16: =BA14+BA15 -> 45889345 | BB16: =BB14+BB15 -> 1.8862678e+08 | BC16: =BC14+BC15 -> 2.3450423e+08 | BD16: =BD14+BD15 -> 3.9332092e+08 | ... BF16: =BF14+BF15 -> 5.6416642e+09 | BI16: =BI14+BI15 -> 1.7108164e+09 | BJ16: =BJ14+BJ15 -> 1.4943132e+09 | BK16: =BK14+BK15 -> 9128674.3 | BL16: =BL14+BL15 -> 2.5209292e+09 | BM16: =BM14+BM15 -> 55067214 | BN16: =BN14+BN15 -> 2.2635213e+08 | BO16: =BO14+BO15 -> 2.8140507e+08 | BP16: =BP14+BP15 -> 4.7198511e+08 | ... BR16: =BR14+BR15 -> 6.769997e+09 | BU16: =BU14+BU15 -> 1.9959525e+09 | BV16: =BV14+BV15 -> 1.7433654e+09 | BW16: =BW14+BW15 -> 10650120 | BX16: =BX14+BX15 -> 2.941084e+09 | BY16: =BY14+BY15 -> 64245083 | BZ16: =BZ14+BZ15 -> 2.6407749e+08 | CA16: =CA14+CA15 -> 3.2830592e+08 | CB16: =CB14+CB15 -> 5.5064929e+08 | ... CD16: =CD14+CD15 -> 7.8983298e+09 | CG16: =CG14+CG15 -> 2.2810886e+09 | CH16: =CH14+CH15 -> 1.9924176e+09 | CI16: =CI14+CI15 -> 12171566 | CJ16: =CJ14+CJ15 -> 3.3612389e+09 | CK16: =CK14+CK15 -> 73422952 | CL16: =CL14+CL15 -> 3.0180284e+08 | CM16: =CM14+CM15 -> 3.7520676e+08 | CN16: =CN14+CN15 -> 6.2931348e+08 | ... CP16: =CP14+CP15 -> 9.0266627e+09 | CS16: =CS14+CS15 -> 2.5662246e+09 | CT16: =CT14+CT15 -> 2.2414698e+09 | CU16: =CU14+CU15 -> 13693011 | CV16: =CV14+CV15 -> 3.7813938e+09 | CW16: =CW14+CW15 -> 82600821 | CX16: =CX14+CX15 -> 3.395282e+08 | CY16: =CY14+CY15 -> 4.2210761e+08 | CZ16: =CZ14+CZ15 -> 7.0797766e+08 | ... DB16: =DB14+DB15 -> 1.0154995e+10 | DE16: =DE14+DE15 -> 2.8513607e+09 | DF16: =DF14+DF15 -> 2.490522e+09 | DG16: =DG14+DG15 -> 15214457 | DH16: =DH14+DH15 -> 4.2015486e+09 | DI16: =DI14+DI15 -> 91778689 | DJ16: =DJ14+DJ15 -> 3.7725355e+08 | DK16: =DK14+DK15 -> 4.6900845e+08 | DL16: =DL14+DL15 -> 7.8664185e+08 | ... DN16: =DN14+DN15 -> 6.0335354e+18 | DQ16: =DQ14+DQ15 -> 3.1364968e+09 | DR16: =DR14+DR15 -> 2.7395742e+09 | DS16: =DS14+DS15 -> 16735903 | DT16: =DT14+DT15 -> 4.6217035e+09 | DU16: =DU14+DU15 -> 1.0095656e+08 | DV16: =DV14+DV15 -> 4.1497891e+08 | DW16: =DW14+DW15 -> 5.159093e+08 | DX16: =DX14+DX15 -> 8.6530603e+08 | ... DZ16: =DZ14+DZ15 -> 1.2411661e+10 | EC16: =EC14+EC15 -> 3.4216328e+09 | ED16: =ED14+ED15 -> 2.9886264e+09 | EE16: =EE14+EE15 -> 18257349 | EF16: =EF14+EF15 -> 5.0418583e+09 | EG16: =EG14+EG15 -> 1.1013443e+08 | EH16: =EH14+EH15 -> 4.5270426e+08 | EI16: =EI14+EI15 -> 5.6281014e+08 | EJ16: =EJ14+EJ15 -> 9.4397021e+08 | ... EL16: =EL14+EL15 -> 1.3539994e+10
A18: Commisions | B18: =B7*'Hyp 2027'!B206 -> 2.8933599e+08 | C18: =C7*'Hyp 2027'!C206 -> 2.6289225e+08 | D18: =D7*'Hyp 2027'!D206 -> 2284409.8 | E18: =E7*'Hyp 2027'!E206 -> 1.3164869e+08 | F18: =F7*'Hyp 2027'!F206 -> 14407617 | G18: =G7*'Hyp 2027'!G206 -> 5478482.6 | H18: =H7*'Hyp 2027'!H206 -> 86839861 | I18: =I7*'Hyp 2027'!I206 -> 3831707.1 | J18: =SUM(D18:I18) -> 2.4449077e+08 | K18: =B18+C18+J18 -> 7.9671901e+08 | L18: ok | M18: =M7*'Hyp 2027'!B207 -> 3.058679e+08 | N18: =N7*'Hyp 2027'!C207 -> 2.8541947e+08 | O18: =O7*'Hyp 2027'!D207 -> 6654772 | P18: =P7*'Hyp 2027'!E207 -> 5.2586342e+08 | Q18: =Q7*'Hyp 2027'!F207 -> 58567754 | R18: =R7*'Hyp 2027'!G207 -> 29043706 | S18: =S7*'Hyp 2027'!H207 -> 1.7628145e+08 | T18: =T7*'Hyp 2027'!I207 -> 1.9971079e+08 | U18: =SUM(O18:T18) -> 9.9612189e+08 | V18: =M18+N18+U18 -> 1.5874093e+09 | Y18: =Y7*'Hyp 2027'!B208 -> 4.5500919e+08 | Z18: =Z7*'Hyp 2027'!C208 -> 3.563379e+08 | AA18: =AA7*'Hyp 2027'!D208 -> 6845621.4 | AB18: =AB7*'Hyp 2027'!E208 -> 6.8681066e+08 | AC18: =AC7*'Hyp 2027'!F208 -> 85425129 | AD18: =AD7*'Hyp 2027'!G208 -> 33053886 | AE18: =AE7*'Hyp 2027'!H208 -> 2.396915e+08 | AF18: =AF7*'Hyp 2027'!I208 -> 2.5817722e+08 | AG18: =SUM(AA18:AF18) -> 1.310004e+09 | AH18: =Y18+Z18+AG18 -> 2.1213511e+09 | AK18: ='Hyp 2027'!B209*AK7 -> 4.8901483e+08 | AL18: ='Hyp 2027'!C209*AL7 -> 3.8568469e+08 | AM18: ='Hyp 2027'!D209*AM7 -> 9480095.8 | AN18: ='Hyp 2027'!E209*AN7 -> 9.0763237e+08 | AO18: ='Hyp 2027'!F209*AO7 -> 1.0553262e+08 | AP18: ='Hyp 2027'!G209*AP7 -> 96840590 | AQ18: ='Hyp 2027'!H209*AQ7 -> 2.7574275e+08 | AR18: ='Hyp 2027'!I209*AR7 -> 2.6134773e+08 | AS18: =SUM(AM18:AR18) -> 1.6565762e+09 | AT18: =AK18+AL18+AS18 -> 2.5312757e+09 | AW18: =AW7*'Hyp 2027'!B210 -> 6.1286128e+08 | AX18: =AX7*'Hyp 2027'!C210 -> 4.4533993e+08 | AY18: =AY7*'Hyp 2027'!D210 -> 12899708 | AZ18: =AZ7*'Hyp 2027'!E210 -> 9.6473661e+08 | BA18: =BA7*'Hyp 2027'!F210 -> 1.3047392e+08 | BB18: =BB7*'Hyp 2027'!G210 -> 1.1447044e+08 | BC18: =BC7*'Hyp 2027'!H210 -> 1.9635179e+08 | BD18: =BD7*'Hyp 2027'!I210 -> 3.5351681e+08 | BE18: ='Hyp 2027'!J82*'Hyp 2027'!J166 -> 0 | BF18: =AW18+AX18+BE18 -> 1.0582012e+09 | BI18: =BI7*'Hyp 2027'!B211 -> 6.6150726e+08 | BJ18: =BJ7*'Hyp 2027'!C211 -> 4.6376177e+08 | BK18: =BK7*'Hyp 2027'!D211 -> 16147775 | BL18: =BL7*'Hyp 2027'!E211 -> 1.1110123e+09 | BM18: =BM7*'Hyp 2027'!F211 -> 1.3287997e+08 | BN18: =BN7*'Hyp 2027'!G211 -> 1.2141552e+08 | BO18: =BO7*'Hyp 2027'!H211 -> 2.0621319e+08 | BP18: =BP7*'Hyp 2027'!I211 -> 3.7608409e+08 | BQ18: =SUM(BK18:BP18) -> 1.9637528e+09 | BR18: =BI18+BJ18+BQ18 -> 3.0890219e+09 | BU18: =BU7*'Hyp 2027'!B212 -> 7.0597512e+08 | BV18: =BV7*'Hyp 2027'!C212 -> 4.9102774e+08 | BW18: =BW7*'Hyp 2027'!D212 -> 17208804 | BX18: =BX7*'Hyp 2027'!E212 -> 1.127948e+09 | BY18: =BY7*'Hyp 2027'!F212 -> 1.409787e+08 | BZ18: =BZ7*'Hyp 2027'!G212 -> 1.2748256e+08 | CA18: =CA7*'Hyp 2027'!H212 -> 2.1514244e+08 | CB18: =CB7*'Hyp 2027'!I212 -> 3.9988129e+08 | CC18: =SUM(BW18:CB18) -> 2.0286418e+09 | CD18: =BU18+BV18+CC18 -> 3.2256447e+09 | CG18: =CG7*'Hyp 2027'!B169 -> 1.0633756e+09 | CH18: =CH7*'Hyp 2027'!C169 -> 5.3765967e+08 | CI18: =CI7*'Hyp 2027'!D169 -> 17677519 | CJ18: =CJ7*'Hyp 2027'!E169 -> 1.0472973e+09 | CK18: =CK7*'Hyp 2027'!F169 -> 1.0792026e+08 | CL18: =CL7*'Hyp 2027'!G169 -> 2.1981041e+08 | CM18: =CM7*'Hyp 2027'!H169 -> 2.6546557e+08 | CN18: =CN7*'Hyp 2027'!I169 -> 4.1104925e+08 | CO18: =SUM(CI18:CN18) -> 2.0692203e+09 | CP18: =CG18+CH18+CO18 -> 3.6702555e+09 | CS18: =CS7*'Hyp 2027'!B169 -> 1.127958e+09 | CT18: =CT7*'Hyp 2027'!C169 -> 5.6259375e+08 | CU18: =CU7*'Hyp 2027'!D169 -> 18122446 | CV18: =CV7*'Hyp 2027'!E169 -> 1.1107501e+09 | CW18: =CW7*'Hyp 2027'!F169 -> 1.0849804e+08 | CX18: =CX7*'Hyp 2027'!G169 -> 2.6183853e+08 | CY18: =CY7*'Hyp 2027'!H169 -> 2.7328225e+08 | CZ18: =CZ7*'Hyp 2027'!I169 -> 4.4148898e+08 | DA18: =SUM(CU18:CZ18) -> 2.2139804e+09 | DB18: =CS18+CT18+DA18 -> 3.9045321e+09 | DE18: =DE7*'Hyp 2027'!B169 -> 1.2067811e+09 | DF18: =DF7*'Hyp 2027'!C169 -> 6.0201175e+08 | DG18: =DG7*'Hyp 2027'!D169 -> 18990149 | DH18: =DH7*'Hyp 2027'!E169 -> 1.157914e+09 | DI18: =DI7*'Hyp 2027'!F169 -> 1.0997553e+08 | DJ18: =DJ7*'Hyp 2027'!G169 -> 2.6646666e+08 | DK18: =DK7*'Hyp 2027'!H169 -> 2.934589e+08 | DL18: =DL7*'Hyp 2027'!I169 -> 4.7258089e+08 | DM18: =SUM(DG18:DL18) -> 2.3193861e+09 | DN18: =DE18+DF18+DM18 -> 4.1281789e+09 | DQ18: =DQ7*'Hyp 2027'!B169 -> 1.2834919e+09 | DR18: =DR7*'Hyp 2027'!C169 -> 6.3019492e+08 | DS18: =DS7*'Hyp 2027'!D169 -> 19705428 | DT18: =DT7*'Hyp 2027'!E169 -> 1.176951e+09 | DU18: =DU7*'Hyp 2027'!F169 -> 1.1598299e+08 | DV18: =DV7*'Hyp 2027'!G169 -> 2.7647594e+08 | DW18: =DW7*'Hyp 2027'!H169 -> 3.4423599e+08 | DX18: =DX7*'Hyp 2027'!I169 -> 5.1579732e+08 | DY18: =SUM(DS18:DX18) -> 2.4491487e+09 | DZ18: =DQ18+DR18+DY18 -> 4.3628355e+09 | EC18: ='Hyp 2027'!B169*'Direct Local'!EC7 -> 1.3424177e+09 | ED18: ='Hyp 2027'!C169*'Direct Local'!ED7 -> 6.3810494e+08 | EE18: ='Hyp 2027'!D169*'Direct Local'!EE7 -> 21104246 | EF18: ='Hyp 2027'!E169*'Direct Local'!EF7 -> 1.2064072e+09 | EG18: ='Hyp 2027'!F169*'Direct Local'!EG7 -> 1.2425175e+08 | EH18: ='Hyp 2027'!G169*'Direct Local'!EH7 -> 2.8200432e+08 | EI18: ='Hyp 2027'!H169*'Direct Local'!EI7 -> 3.5542921e+08 | EJ18: ='Hyp 2027'!I169*'Direct Local'!EJ7 -> 5.3334201e+08 | EK18: =SUM(EE18:EJ18) -> 2.5225387e+09 | EL18: =EC18+ED18+EK18 -> 4.5030614e+09
